test/trades.csv
order_id,side,quantity,price
AAA,buy,10,10
BBB,buy,12,12
CCC,buy,14,14
CCC,cancel,,
DDD,sell,10,15
EEE,sell,2,12
FFF,sell,4,12
GGG,sell,10,12
BBB,cancel,,
HHH,buy,14,12
KKK,sell,20,10
DDD,cancel,,
DDD,cancel,,
